Watching for file changes with StatReloader
Performing system checks...

D:\data\data\cloud\code\Decetion\my_detection\deploy
D:\data\data\cloud\code\Decetion\my_detection\deploy
Warning: Unable to use numba in PP-Tracking, please install numba, for example(python3.7): `pip install numba==0.56.4`
Warning: Unable to use numba in PP-Tracking, please install numba, for example(python3.7): `pip install numba==0.56.4`
Warning: Unable to use numba in PP-Tracking, please install numba, for example(python3.7): `pip install numba==0.56.4`
Warning: Unable to use numba in PP-Tracking, please install numba, for example(python3.7): `pip install numba==0.56.4`
Exception in thread django-main-thread:
Traceback (most recent call last):
  File "C:\Users\11925\anaconda3\envs\paddle\lib\threading.py", line 980, in _bootstrap_inner
    self.run()
  File "C:\Users\11925\anaconda3\envs\paddle\lib\threading.py", line 917, in run
    self._target(*self._args, **self._kwargs)
  File "C:\Users\11925\anaconda3\envs\paddle\lib\site-packages\django\utils\autoreload.py", line 64, in wrapper
    fn(*args, **kwargs)
  File "C:\Users\11925\anaconda3\envs\paddle\lib\site-packages\django\core\management\commands\runserver.py", line 133, in inner_run
    self.check(display_num_errors=True)
  File "C:\Users\11925\anaconda3\envs\paddle\lib\site-packages\django\core\management\base.py", line 485, in check
    all_issues = checks.run_checks(
  File "C:\Users\11925\anaconda3\envs\paddle\lib\site-packages\django\core\checks\registry.py", line 88, in run_checks
    new_errors = check(app_configs=app_configs, databases=databases)
  File "C:\Users\11925\anaconda3\envs\paddle\lib\site-packages\django\core\checks\urls.py", line 14, in check_url_config
    return check_resolver(resolver)
  File "C:\Users\11925\anaconda3\envs\paddle\lib\site-packages\django\core\checks\urls.py", line 24, in check_resolver
    return check_method()
  File "C:\Users\11925\anaconda3\envs\paddle\lib\site-packages\django\urls\resolvers.py", line 494, in check
    for pattern in self.url_patterns:
  File "C:\Users\11925\anaconda3\envs\paddle\lib\site-packages\django\utils\functional.py", line 57, in __get__
    res = instance.__dict__[self.name] = self.func(instance)
  File "C:\Users\11925\anaconda3\envs\paddle\lib\site-packages\django\urls\resolvers.py", line 715, in url_patterns
    patterns = getattr(self.urlconf_module, "urlpatterns", self.urlconf_module)
  File "C:\Users\11925\anaconda3\envs\paddle\lib\site-packages\django\utils\functional.py", line 57, in __get__
    res = instance.__dict__[self.name] = self.func(instance)
  File "C:\Users\11925\anaconda3\envs\paddle\lib\site-packages\django\urls\resolvers.py", line 708, in urlconf_module
    return import_module(self.urlconf_name)
  File "C:\Users\11925\anaconda3\envs\paddle\lib\importlib\__init__.py", line 127, in import_module
    return _bootstrap._gcd_import(name[level:], package, level)
  File "<frozen importlib._bootstrap>", line 1030, in _gcd_import
  File "<frozen importlib._bootstrap>", line 1007, in _find_and_load
  File "<frozen importlib._bootstrap>", line 986, in _find_and_load_unlocked
  File "<frozen importlib._bootstrap>", line 680, in _load_unlocked
  File "<frozen importlib._bootstrap_external>", line 850, in exec_module
  File "<frozen importlib._bootstrap>", line 228, in _call_with_frames_removed
  File "D:\data\data\cloud\code\Decetion\AIdjango\mydjango\urls.py", line 3, in <module>
    from user.gen_display import video,upload_video,video_view,upload_photo,ConfirmParams,photo_view, close_camera, open_camera,video_record,close_camera_record,getAllRecordFile,get_progress
  File "D:\data\data\cloud\code\Decetion\AIdjango\user\gen_display.py", line 39, in <module>
    from PyCameraList.camera_device import test_list_cameras, list_video_devices, list_audio_devices
ModuleNotFoundError: No module named 'PyCameraList'
